Workbook

Sheet master
A1: date | B1: remit | C1: typhoon | D1: ex | E1: inf | F1: int | G1: unem | H1: ggrowth
A2: 41640 | B2: =remit!B2 -> 1608714 | C2: =IFERROR(__xludf.DUMMYFUNCTION("FILTER(FLATTEN(philippines_typhoon_monthly_201!N2:N1001), FLATTEN(philippines_typhoon_monthly_201!N2:N1001) <> """") "),1.0) -> 1 | D2: =ex!B2 -> 44.935667 | E2: =inf!B2 -> 3.6 | F2: =int!B2 -> 0.53733333 | G2: =unem!B2 -> 7.5 | H2: =ggrowth!B2 -> 9.5
A3: 41730 | B3: =remit!B3 -> 1738037 | C3: =IFERROR(__xludf.DUMMYFUNCTION("""COMPUTED_VALUE"""),3.0) -> 3 | D3: =ex!B3 -> 44.056667 | E3: =inf!B3 -> 3.8 | F3: =int!B3 -> 0.62766667 | G3: =unem!B3 -> 7 | H3: =ggrowth!B3 -> 10.1
A4: 41821 | B4: =remit!B4 -> 1965309 | C4: =IFERROR(__xludf.DUMMYFUNCTION("""COMPUTED_VALUE"""),7.0) -> 7 | D4: =ex!B4 -> 44.011667 | E4: =inf!B4 -> 4.1 | F4: =int!B4 -> 0.64633333 | G4: =unem!B4 -> 6.7 | H4: =ggrowth!B4 -> 8.9
A5: 41913 | B5: =remit!B5 -> 2091473 | C5: =IFERROR(__xludf.DUMMYFUNCTION("""COMPUTED_VALUE"""),5.0) -> 5 | D5: =ex!B5 -> 44.803 | E5: =inf!B5 -> 2.8666667 | F5: =int!B5 -> 0.70266667 | G5: =unem!B5 -> 6 | H5: =ggrowth!B5 -> 9.8
A6: 42005 | B6: =remit!B6 -> 2202824 | C6: =IFERROR(__xludf.DUMMYFUNCTION("""COMPUTED_VALUE"""),1.0) -> 1 | D6: =ex!B6 -> 44.338333 | E6: =inf!B6 -> 1.5 | F6: =int!B6 -> 0.71733333 | G6: =unem!B6 -> 6.6 | H6: =ggrowth!B6 -> 5.5
A7: 42095 | B7: =remit!B7 -> 2056654 | C7: =IFERROR(__xludf.DUMMYFUNCTION("""COMPUTED_VALUE"""),1.0) -> 1 | D7: =ex!B7 -> 44.7 | E7: =inf!B7 -> 0.96666667 | F7: =int!B7 -> 0.672 | G7: =unem!B7 -> 6.4 | H7: =ggrowth!B7 -> 6
A8: 42186 | B8: =remit!B8 -> 2139711 | C8: =IFERROR(__xludf.DUMMYFUNCTION("""COMPUTED_VALUE"""),2.0) -> 2 | D8: =ex!B8 -> 46.416333 | E8: =inf!B8 -> -0.066666667 | F8: =int!B8 -> 0.72133333 | G8: =unem!B8 -> 6.5 | H8: =ggrowth!B8 -> 4.9
A9: 42278 | B9: =remit!B9 -> 2009401 | C9: =IFERROR(__xludf.DUMMYFUNCTION("""COMPUTED_VALUE"""),5.0) -> 5 | D9: =ex!B9 -> 47.041667 | E9: =inf!B9 -> 0.26666667 | F9: =int!B9 -> 0.72733333 | G9: =unem!B9 -> 5.7 | H9: =ggrowth!B9 -> 5.8
A10: 42370 | B10: =remit!B10 -> 2044177 | C10: =IFERROR(__xludf.DUMMYFUNCTION("""COMPUTED_VALUE"""),0.0) -> 0 | D10: =ex!B10 -> 47.163667 | E10: =inf!B10 -> 0.6 | F10: =int!B10 -> 0.71733333 | G10: =unem!B10 -> 5.8 | H10: =ggrowth!B10 -> 7.3
A11: 42461 | B11: =remit!B11 -> 2235404 | C11: =IFERROR(__xludf.DUMMYFUNCTION("""COMPUTED_VALUE"""),3.0) -> 3 | D11: =ex!B11 -> 46.836 | E11: =inf!B11 -> 0.96666667 | F11: =int!B11 -> 0.672 | G11: =unem!B11 -> 6.1 | H11: =ggrowth!B11 -> 8.5
A12: 42552 | B12: =remit!B12 -> 2316851 | C12: =IFERROR(__xludf.DUMMYFUNCTION("""COMPUTED_VALUE"""),5.0) -> 5 | D12: =ex!B12 -> 47.269667 | E12: =inf!B12 -> 1.4333333 | F12: =int!B12 -> 0.72133333 | G12: =unem!B12 -> 5.4 | H12: =ggrowth!B12 -> 9.4
A13: 42644 | B13: =remit!B13 -> 2334837 | C13: =IFERROR(__xludf.DUMMYFUNCTION("""COMPUTED_VALUE"""),9.0) -> 9 | D13: =ex!B13 -> 49.368333 | E13: =inf!B13 -> 2.0333333 | F13: =int!B13 -> 0.72733333 | G13: =unem!B13 -> 4.7 | H13: =ggrowth!B13 -> 8.8
A14: 42736 | B14: =remit!B14 -> 2277222 | C14: =IFERROR(__xludf.DUMMYFUNCTION("""COMPUTED_VALUE"""),1.0) -> 1 | D14: =ex!B14 -> 50.091667 | E14: =inf!B14 -> 2.9 | F14: =int!B14 -> 0.68866667 | G14: =unem!B14 -> 6.6 | H14: =ggrowth!B14 -> 9
A15: 42826 | B15: =remit!B15 -> 2289870 | C15: =IFERROR(__xludf.DUMMYFUNCTION("""COMPUTED_VALUE"""),4.0) -> 4 | D15: =ex!B15 -> 50.010667 | E15: =inf!B15 -> 2.8666667 | F15: =int!B15 -> 0.66533333 | G15: =unem!B15 -> 5.7 | H15: =ggrowth!B15 -> 9.6
A16: 42917 | B16: =remit!B16 -> 2395900 | C16: =IFERROR(__xludf.DUMMYFUNCTION("""COMPUTED_VALUE"""),8.0) -> 8 | D16: =ex!B16 -> 50.940333 | E16: =inf!B16 -> 2.6666667 | F16: =int!B16 -> 0.698 | G16: =unem!B16 -> 5.6 | H16: =ggrowth!B16 -> 10.2
A17: 43009 | B17: =remit!B17 -> 2459318 | C17: =IFERROR(__xludf.DUMMYFUNCTION("""COMPUTED_VALUE"""),5.0) -> 5 | D17: =ex!B17 -> 50.695667 | E17: =inf!B17 -> 3 | F17: =int!B17 -> 0.688 | G17: =unem!B17 -> 5 | H17: =ggrowth!B17 -> 8.9
A18: 43101 | B18: =remit!B18 -> 2362752 | C18: =IFERROR(__xludf.DUMMYFUNCTION("""COMPUTED_VALUE"""),2.0) -> 2 | D18: =ex!B18 -> 51.887333 | E18: =inf!B18 -> 3.8 | F18: =int!B18 -> 0.742 | G18: =unem!B18 -> 5.3 | H18: =ggrowth!B18 -> 9.5
A19: 43191 | B19: =remit!B19 -> 2477790 | C19: =IFERROR(__xludf.DUMMYFUNCTION("""COMPUTED_VALUE"""),0.0) -> 0 | D19: =ex!B19 -> 52.725333 | E19: =inf!B19 -> 4.6333333 | F19: =int!B19 -> 0.78433333 | G19: =unem!B19 -> 5.5 | H19: =ggrowth!B19 -> 10
A20: 43282 | B20: =remit!B20 -> 2529585 | C20: =IFERROR(__xludf.DUMMYFUNCTION("""COMPUTED_VALUE"""),6.0) -> 6 | D20: =ex!B20 -> 53.649333 | E20: =inf!B20 -> 6.4333333 | F20: =int!B20 -> 0.91866667 | G20: =unem!B20 -> 5.4 | H20: =ggrowth!B20 -> 10.8
A21: 43374 | B21: =remit!B21 -> 2616266 | C21: =IFERROR(__xludf.DUMMYFUNCTION("""COMPUTED_VALUE"""),5.0) -> 5 | D21: =ex!B21 -> 52.979333 | E21: =inf!B21 -> 6.0666667 | F21: =int!B21 -> 1.1343333 | G21: =unem!B21 -> 5.1 | H21: =ggrowth!B21 -> 10.9
A22: 43466 | B22: =remit!B22 -> 2562924 | C22: =IFERROR(__xludf.DUMMYFUNCTION("""COMPUTED_VALUE"""),1.0) -> 1 | D22: =ex!B22 -> 52.38 | E22: =inf!B22 -> 3.8666667 | F22: =int!B22 -> 1.3503333 | G22: =unem!B22 -> 5.2 | H22: =ggrowth!B22 -> 7.9
A23: 43556 | B23: =remit!B23 -> 2759732 | C23: =IFERROR(__xludf.DUMMYFUNCTION("""COMPUTED_VALUE"""),4.0) -> 4 | D23: =ex!B23 -> 51.907 | E23: =inf!B23 -> 3.0333333 | F23: =int!B23 -> 1.3093333 | G23: =unem!B23 -> 5.1 | H23: =ggrowth!B23 -> 6.5
A24: 43647 | B24: =remit!B24 -> 2986578 | C24: =IFERROR(__xludf.DUMMYFUNCTION("""COMPUTED_VALUE"""),3.0) -> 3 | D24: =ex!B24 -> 51.798 | E24: =inf!B24 -> 1.3666667 | F24: =int!B24 -> 1.2786667 | G24: =unem!B24 -> 5.4 | H24: =ggrowth!B24 -> 6.2
A25: 43739 | B25: =remit!B25 -> 3009099 | C25: =IFERROR(__xludf.DUMMYFUNCTION("""COMPUTED_VALUE"""),6.0) -> 6 | D25: =ex!B25 -> 50.858333 | E25: =inf!B25 -> 1.4 | F25: =int!B25 -> 0.989 | G25: =unem!B25 -> 4.5 | H25: =ggrowth!B25 -> 6.9
A26: 43831 | B26: =remit!B26 -> 2885272 | C26: =IFERROR(__xludf.DUMMYFUNCTION("""COMPUTED_VALUE"""),3.0) -> 3 | D26: =ex!B26 -> 50.961667 | E26: =inf!B26 -> 2.5666667 | F26: =int!B26 -> 0.35833333 | G26: =unem!B26 -> 5.3 | H26: =ggrowth!B26 -> 0.5
A27: 43922 | B27: =remit!B27 -> 2681014 | C27: =IFERROR(__xludf.DUMMYFUNCTION("""COMPUTED_VALUE"""),4.0) -> 4 | D27: =ex!B27 -> 50.389 | E27: =inf!B27 -> 1.9 | F27: =int!B27 -> 0.38666667 | G27: =unem!B27 -> 17.6 | H27: =ggrowth!B27 -> -15
A28: 44013 | B28: =remit!B28 -> 3210620 | C28: =IFERROR(__xludf.DUMMYFUNCTION("""COMPUTED_VALUE"""),9.0) -> 9 | D28: =ex!B28 -> 48.767667 | E28: =inf!B28 -> 2.2666667 | F28: =int!B28 -> 0.388 | G28: =unem!B28 -> 10 | H28: =ggrowth!B28 -> -11
A29: 44105 | B29: =remit!B29 -> 3159448 | C29: =IFERROR(__xludf.DUMMYFUNCTION("""COMPUTED_VALUE"""),9.0) -> 9 | D29: =ex!B29 -> 48.179667 | E29: =inf!B29 -> 2.8666667 | F29: =int!B29 -> 0.31033333 | G29: =unem!B29 -> 8.7 | H29: =ggrowth!B29 -> -6.2
A30: 44197 | B30: =remit!B30 -> 3096814 | C30: =IFERROR(__xludf.DUMMYFUNCTION("""COMPUTED_VALUE"""),1.0) -> 1 | D30: =ex!B30 -> 48.408 | E30: =inf!B30 -> 4 | F30: =int!B30 -> 0.20733333 | G30: =unem!B30 -> 8.2333333 | H30: =ggrowth!B30 -> -1.7
A31: 44287 | B31: =remit!B31 -> 2886153 | C31: =IFERROR(__xludf.DUMMYFUNCTION("""COMPUTED_VALUE"""),1.0) -> 1 | D31: =ex!B31 -> 48.278333 | E31: =inf!B31 -> 3.9666667 | F31: =int!B31 -> 0.21666667 | G31: =unem!B31 -> 8.0333333 | H31: =ggrowth!B31 -> 15.2
A32: 44378 | B32: =remit!B32 -> 3456173 | C32: =IFERROR(__xludf.DUMMYFUNCTION("""COMPUTED_VALUE"""),5.0) -> 5 | D32: =ex!B32 -> 50.447 | E32: =inf!B32 -> 4.1 | F32: =int!B32 -> 0.29933333 | G32: =unem!B32 -> 8.0666667 | H32: =ggrowth!B32 -> 9.5
A33: 44470 | B33: =remit!B33 -> 3296836 | C33: =IFERROR(__xludf.DUMMYFUNCTION("""COMPUTED_VALUE"""),7.0) -> 7 | D33: =ex!B33 -> 50.667333 | E33: =inf!B33 -> 3.6 | F33: =int!B33 -> 0.44133333 | G33: =unem!B33 -> 6.8333333 | H33: =ggrowth!B33 -> 9.8
A34: 44562 | B34: =remit!B34 -> 3223467 | C34: =IFERROR(__xludf.DUMMYFUNCTION("""COMPUTED_VALUE"""),0.0) -> 0 | D34: =ex!B34 -> 51.508 | E34: =inf!B34 -> 3.3333333 | F34: =int!B34 -> 0.38666667 | G34: =unem!B34 -> 6.2 | H34: =ggrowth!B34 -> 12.7
A35: 44652 | B35: =remit!B35 -> 3091002 | C35: =IFERROR(__xludf.DUMMYFUNCTION("""COMPUTED_VALUE"""),3.0) -> 3 | D35: =ex!B35 -> 53.140667 | E35: =inf!B35 -> 5.4666667 | F35: =int!B35 -> 0.405 | G35: =unem!B35 -> 5.9 | H35: =ggrowth!B35 -> 13.2
A36: 44743 | B36: =remit!B36 -> 3623743 | C36: =IFERROR(__xludf.DUMMYFUNCTION("""COMPUTED_VALUE"""),8.0) -> 8 | D36: =ex!B36 -> 56.958333 | E36: =inf!B36 -> 6.5333333 | F36: =int!B36 -> 0.61333333 | G36: =unem!B36 -> 5.1666667 | H36: =ggrowth!B36 -> 14
A37: 44835 | B37: =remit!B37 -> 3458355 | C37: =IFERROR(__xludf.DUMMYFUNCTION("""COMPUTED_VALUE"""),2.0) -> 2 | D37: =ex!B37 -> 57.068 | E37: =inf!B37 -> 7.9333333 | F37: =int!B37 -> 1.0473333 | G37: =unem!B37 -> 4.3333333 | H37: =ggrowth!B37 -> 13.9
A38: 44927 | B38: =remit!B38 -> 3312492 | C38: =IFERROR(__xludf.DUMMYFUNCTION("""COMPUTED_VALUE"""),2.0) -> 2 | D38: =ex!B38 -> 54.762 | E38: =inf!B38 -> 8.3 | F38: =int!B38 -> 1.2903333 | G38: =unem!B38 -> 4.7666667 | H38: =ggrowth!B38 -> 13.9
A39: 45017 | B39: =remit!B39 -> 3175830 | C39: =IFERROR(__xludf.DUMMYFUNCTION("""COMPUTED_VALUE"""),0.0) -> 0 | D39: =ex!B39 -> 55.788 | E39: =inf!B39 -> 6.0333333 | F39: =int!B39 -> 1.5473333 | G39: =unem!B39 -> 4.4333333 | H39: =ggrowth!B39 -> 9.1
A40: 45108 | B40: =remit!B40 -> 3686060 | C40: =IFERROR(__xludf.DUMMYFUNCTION("""COMPUTED_VALUE"""),8.0) -> 8 | D40: =ex!B40 -> 56.17 | E40: =inf!B40 -> 5.3666667 | F40: =int!B40 -> 1.747 | G40: =unem!B40 -> 4.6 | H40: =ggrowth!B40 -> 9.7
...

Sheet remit
A1: date | B1: remittances (sum) | D1: jan | E1: feb | F1: mar | G1: apr | H1: may | I1: jun | J1: jul | K1: aug | L1: sep | M1: oct | N1: nov | O1: dec
A2: 41640 | B2: =IFERROR(__xludf.DUMMYFUNCTION("FILTER(FLATTEN({D3:O3; D5:O5; D7:O7; D9:O9; D11:O11; D13:O13; D15:O15; D17:O17; D19:O19; D21:O21; D23:O23}), FLATTEN({D3:O3; D5:O5; D7:O7; D9:O9; D11:O11; D13:O13; D15:O15; D17:O17; D19:O19; D21:O21; D23:O23}) <> """")"),1608714.0) -> 1608714 | C2: 2014 | D2: 500172 | E2: 505976 | F2: 602566 | G2: 572285 | H2: 563105 | I2: 602647 | J2: 648777 | K2: 607106 | L2: 709426 | M2: 712600 | N2: 658685 | O2: 720188
A3: 41730 | B3: =IFERROR(__xludf.DUMMYFUNCTION("""COMPUTED_VALUE"""),1738037.0) -> 1738037 | D3: =SUM(D2:F2) -> 1608714 | G3: =SUM(G2:I2) -> 1738037 | J3: =SUM(J2:L2) -> 1965309 | M3: =SUM(M2:O2) -> 2091473
A4: 41821 | B4: =IFERROR(__xludf.DUMMYFUNCTION("""COMPUTED_VALUE"""),1965309.0) -> 1965309 | C4: 2015 | D4: 694818 | E4: 703613 | F4: 804393 | G4: 671981 | H4: 645066 | I4: 739607 | J4: 765249 | K4: 677694 | L4: 696768 | M4: 677318 | N4: 582272 | O4: 749811
A5: 41913 | B5: =IFERROR(__xludf.DUMMYFUNCTION("""COMPUTED_VALUE"""),2091473.0) -> 2091473 | D5: =SUM(D4:F4) -> 2202824 | G5: =SUM(G4:I4) -> 2056654 | J5: =SUM(J4:L4) -> 2139711 | M5: =SUM(M4:O4) -> 2009401
A6: 42005 | B6: =IFERROR(__xludf.DUMMYFUNCTION("""COMPUTED_VALUE"""),2202824.0) -> 2202824 | C6: 2016 | D6: 639309 | E6: 638899 | F6: 765969 | G6: 725334 | H6: 732436 | I6: 777634 | J6: 720380 | K6: 789155 | L6: 807316 | M6: 727360 | N6: 743409 | O6: 864068
A7: 42095 | B7: =IFERROR(__xludf.DUMMYFUNCTION("""COMPUTED_VALUE"""),2056654.0) -> 2056654 | D7: =SUM(D6:F6) -> 2044177 | G7: =SUM(G6:I6) -> 2235404 | J7: =SUM(J6:L6) -> 2316851 | M7: =SUM(M6:O6) -> 2334837
A8: 42186 | B8: =IFERROR(__xludf.DUMMYFUNCTION("""COMPUTED_VALUE"""),2139711.0) -> 2139711 | C8: 2017 | D8: 698280 | E8: 720879 | F8: 858063 | G8: 717286 | H8: 749890 | I8: 822694 | J8: 790342 | K8: 809123 | L8: 796435 | M8: 777030 | N8: 768570 | O8: 913718
A9: 42278 | B9: =IFERROR(__xludf.DUMMYFUNCTION("""COMPUTED_VALUE"""),2009401.0) -> 2009401 | D9: =SUM(D8:F8) -> 2277222 | G9: =SUM(G8:I8) -> 2289870 | J9: =SUM(J8:L8) -> 2395900 | M9: =SUM(M8:O8) -> 2459318
A10: 42370 | B10: =IFERROR(__xludf.DUMMYFUNCTION("""COMPUTED_VALUE"""),2044177.0) -> 2044177 | C10: 2018 | D10: 797792 | E10: 747049 | F10: 817911 | G10: 803963 | H10: 808942 | I10: 864885 | J10: 836661 | K10: 878799 | L10: 814125 | M10: 835868 | N10: 791703 | O10: 988695
A11: 42461 | B11: =IFERROR(__xludf.DUMMYFUNCTION("""COMPUTED_VALUE"""),2235404.0) -> 2235404 | D11: =SUM(D10:F10) -> 2362752 | G11: =SUM(G10:I10) -> 2477790 | J11: =SUM(J10:L10) -> 2529585 | M11: =SUM(M10:O10) -> 2616266
A12: 42552 | B12: =IFERROR(__xludf.DUMMYFUNCTION("""COMPUTED_VALUE"""),2316851.0) -> 2316851 | C12: 2019 | D12: 882425 | E12: 814831 | F12: 865668 | G12: 933144 | H12: 944103 | I12: 882485 | J12: 1014950 | K12: 988723 | L12: 982905 | M12: 1037423 | N12: 926558 | O12: 1045118
A13: 42644 | B13: =IFERROR(__xludf.DUMMYFUNCTION("""COMPUTED_VALUE"""),2334837.0) -> 2334837 | D13: =SUM(D12:F12) -> 2562924 | G13: =SUM(G12:I12) -> 2759732 | J13: =SUM(J12:L12) -> 2986578 | M13: =SUM(M12:O12) -> 3009099
A14: 42736 | B14: =IFERROR(__xludf.DUMMYFUNCTION("""COMPUTED_VALUE"""),2277222.0) -> 2277222 | C14: 2020 | D14: 1021205 | E14: 931979 | F14: 932088 | G14: 857860 | H14: 805719 | I14: 1017435 | J14: 1167280 | K14: 1017109 | L14: 1026231 | M14: 1122014 | N14: 925344 | O14: 1112090
A15: 42826 | B15: =IFERROR(__xludf.DUMMYFUNCTION("""COMPUTED_VALUE"""),2289870.0) -> 2289870 | D15: =SUM(D14:F14) -> 2885272 | G15: =SUM(G14:I14) -> 2681014 | J15: =SUM(J14:L14) -> 3210620 | M15: =SUM(M14:O14) -> 3159448
A16: 42917 | B16: =IFERROR(__xludf.DUMMYFUNCTION("""COMPUTED_VALUE"""),2395900.0) -> 2395900 | C16: 2021 | D16: 1063246 | E16: 1017591 | F16: 1015977 | G16: 895221 | H16: 929716 | I16: 1061216 | J16: 1200827 | K16: 1107738 | L16: 1147608 | M16: 1169593 | N16: 967300 | O16: 1159943
A17: 43009 | B17: =IFERROR(__xludf.DUMMYFUNCTION("""COMPUTED_VALUE"""),2459318.0) -> 2459318 | D17: =SUM(D16:F16) -> 3096814 | G17: =SUM(G16:I16) -> 2886153 | J17: =SUM(J16:L16) -> 3456173 | M17: =SUM(M16:O16) -> 3296836
A18: 43101 | B18: =IFERROR(__xludf.DUMMYFUNCTION("""COMPUTED_VALUE"""),2362752.0) -> 2362752 | C18: 2022 | D18: 1098620 | E18: 1053887 | F18: 1070960 | G18: 969716 | H18: 971841 | I18: 1149445 | J18: 1239488 | K18: 1194455 | L18: 1189800 | M18: 1201470 | N18: 1027771 | O18: 1229114
A19: 43191 | B19: =IFERROR(__xludf.DUMMYFUNCTION("""COMPUTED_VALUE"""),2477790.0) -> 2477790 | D19: =SUM(D18:F18) -> 3223467 | G19: =SUM(G18:I18) -> 3091002 | J19: =SUM(J18:L18) -> 3623743 | M19: =SUM(M18:O18) -> 3458355
A20: 43282 | B20: =IFERROR(__xludf.DUMMYFUNCTION("""COMPUTED_VALUE"""),2529585.0) -> 2529585 | C20: 2023 | D20: 1156066 | E20: 1062292 | F20: 1094134 | G20: 1018502 | H20: 991335 | I20: 1165993 | J20: 1274728 | K20: 1210606 | L20: 1200726 | M20: 1225462 | N20: 1041193 | O20: 1268943
A21: 43374 | B21: =IFERROR(__xludf.DUMMYFUNCTION("""COMPUTED_VALUE"""),2616266.0) -> 2616266 | D21: =SUM(D20:F20) -> 3312492 | G21: =SUM(G20:I20) -> 3175830 | J21: =SUM(J20:L20) -> 3686060 | M21: =SUM(M20:O20) -> 3535598
A22: 43466 | B22: =IFERROR(__xludf.DUMMYFUNCTION("""COMPUTED_VALUE"""),2562924.0) -> 2562924 | C22: 2024 | D22: 1184143 | E22: 1087149 | F22: 1119035 | G22: 1044459 | H22: 1033074 | I22: 1176094 | J22: 1308908 | K22: 1212802 | L22: 1246072 | M22: 1251667 | N22: 1051873 | O22: 1298623
A23: 43556 | B23: =IFERROR(__xludf.DUMMYFUNCTION("""COMPUTED_VALUE"""),2759732.0) -> 2759732 | D23: =SUM(D22:F22) -> 3390327 | G23: =SUM(G22:I22) -> 3253627 | J23: =SUM(J22:L22) -> 3767782 | M23: =SUM(M22:O22) -> 3602163
A24: 43647 | B24: =IFERROR(__xludf.DUMMYFUNCTION("""COMPUTED_VALUE"""),2986578.0) -> 2986578
A25: 43739 | B25: =IFERROR(__xludf.DUMMYFUNCTION("""COMPUTED_VALUE"""),3009099.0) -> 3009099
A26: 43831 | B26: =IFERROR(__xludf.DUMMYFUNCTION("""COMPUTED_VALUE"""),2885272.0) -> 2885272
A27: 43922 | B27: =IFERROR(__xludf.DUMMYFUNCTION("""COMPUTED_VALUE"""),2681014.0) -> 2681014
A28: 44013 | B28: =IFERROR(__xludf.DUMMYFUNCTION("""COMPUTED_VALUE"""),3210620.0) -> 3210620
A29: 44105 | B29: =IFERROR(__xludf.DUMMYFUNCTION("""COMPUTED_VALUE"""),3159448.0) -> 3159448
A30: 44197 | B30: =IFERROR(__xludf.DUMMYFUNCTION("""COMPUTED_VALUE"""),3096814.0) -> 3096814
A31: 44287 | B31: =IFERROR(__xludf.DUMMYFUNCTION("""COMPUTED_VALUE"""),2886153.0) -> 2886153
A32: 44378 | B32: =IFERROR(__xludf.DUMMYFUNCTION("""COMPUTED_VALUE"""),3456173.0) -> 3456173
A33: 44470 | B33: =IFERROR(__xludf.DUMMYFUNCTION("""COMPUTED_VALUE"""),3296836.0) -> 3296836
A34: 44562 | B34: =IFERROR(__xludf.DUMMYFUNCTION("""COMPUTED_VALUE"""),3223467.0) -> 3223467
A35: 44652 | B35: =IFERROR(__xludf.DUMMYFUNCTION("""COMPUTED_VALUE"""),3091002.0) -> 3091002
A36: 44743 | B36: =IFERROR(__xludf.DUMMYFUNCTION("""COMPUTED_VALUE"""),3623743.0) -> 3623743
A37: 44835 | B37: =IFERROR(__xludf.DUMMYFUNCTION("""COMPUTED_VALUE"""),3458355.0) -> 3458355
A38: 44927 | B38: =IFERROR(__xludf.DUMMYFUNCTION("""COMPUTED_VALUE"""),3312492.0) -> 3312492
A39: 45017 | B39: =IFERROR(__xludf.DUMMYFUNCTION("""COMPUTED_VALUE"""),3175830.0) -> 3175830
A40: 45108 | B40: =IFERROR(__xludf.DUMMYFUNCTION("""COMPUTED_VALUE"""),3686060.0) -> 3686060
...

Sheet inf
A1: date | B1: inflation rate (average) | E1: 2014 | F1: 2015 | G1: 2016 | H1: 2017 | I1: 2018 | J1: 2019 | K1: 2020 | L1: 2021 | M1: 2022 | N1: 2023 | O1: 2024
A2: 41640 | B2: =IFERROR(__xludf.DUMMYFUNCTION("FLATTEN({E14:E17; F14:F17; G14:G17; H14:H17; I14:I17; J14:J17; K14:K17; L14:L17; M14:M17; N14:N17; O14:O17}) "),3.6) -> 3.6 | D2: jan | E2: 3.7 | F2: 1.5 | G2: 0.7 | H2: 2.5 | I2: 3.4 | J2: 4.4 | K2: 3 | L2: 3.7 | M2: 3 | N2: 8.7 | O2: 2.8
A3: 41730 | B3: =IFERROR(__xludf.DUMMYFUNCTION("""COMPUTED_VALUE"""),3.7999999999999994) -> 3.8 | D3: feb | E3: 3.6 | F3: 1.5 | G3: 0.5 | H3: 3.1 | I3: 3.7 | J3: 3.8 | K3: 2.5 | L3: 4.2 | M3: 3 | N3: 8.6 | O3: 3.4
A4: 41821 | B4: =IFERROR(__xludf.DUMMYFUNCTION("""COMPUTED_VALUE"""),4.1000000000000005) -> 4.1 | D4: mar | E4: 3.5 | F4: 1.5 | G4: 0.6 | H4: 3.1 | I4: 4.3 | J4: 3.4 | K4: 2.2 | L4: 4.1 | M4: 4 | N4: 7.6 | O4: 3.7
A5: 41913 | B5: =IFERROR(__xludf.DUMMYFUNCTION("""COMPUTED_VALUE"""),2.8666666666666667) -> 2.8666667 | D5: apr | E5: 3.6 | F5: 1.4 | G5: 0.7 | H5: 3.2 | I5: 4.3 | J5: 3.2 | K5: 1.8 | L5: 4.1 | M5: 4.9 | N5: 6.6 | O5: 3.8
A6: 42005 | B6: =IFERROR(__xludf.DUMMYFUNCTION("""COMPUTED_VALUE"""),1.5) -> 1.5 | D6: may | E6: 4 | F6: 0.9 | G6: 0.9 | H6: 2.9 | I6: 4.6 | J6: 3.2 | K6: 1.6 | L6: 4.1 | M6: 5.4 | N6: 6.1 | O6: 3.9
A7: 42095 | B7: =IFERROR(__xludf.DUMMYFUNCTION("""COMPUTED_VALUE"""),0.9666666666666667) -> 0.96666667 | D7: jun | E7: 3.8 | F7: 0.6 | G7: 1.3 | H7: 2.5 | I7: 5 | J7: 2.7 | K7: 2.3 | L7: 3.7 | M7: 6.1 | N7: 5.4 | O7: 3.7
A8: 42186 | B8: =IFERROR(__xludf.DUMMYFUNCTION("""COMPUTED_VALUE"""),-0.06666666666666667) -> -0.066666667 | D8: jul | E8: 4.2 | F8: 0.2 | G8: 1.3 | H8: 2.4 | I8: 5.8 | J8: 2.2 | K8: 2.4 | L8: 3.7 | M8: 6.4 | N8: 4.7 | O8: 4.4
A9: 42278 | B9: =IFERROR(__xludf.DUMMYFUNCTION("""COMPUTED_VALUE"""),0.26666666666666666) -> 0.26666667 | D9: aug | E9: 4.2 | F9: 0 | G9: 1.3 | H9: 2.6 | I9: 6.6 | J9: 1.4 | K9: 2.2 | L9: 4.4 | M9: 6.3 | N9: 5.3 | O9: 3.3
A10: 42370 | B10: =IFERROR(__xludf.DUMMYFUNCTION("""COMPUTED_VALUE"""),0.6) -> 0.6 | D10: sep | E10: 3.9 | F10: -0.4 | G10: 1.7 | H10: 3 | I10: 6.9 | J10: 0.5 | K10: 2.2 | L10: 4.2 | M10: 6.9 | N10: 6.1 | O10: 1.9
A11: 42461 | B11: =IFERROR(__xludf.DUMMYFUNCTION("""COMPUTED_VALUE"""),0.9666666666666668) -> 0.96666667 | D11: oct | E11: 3.7 | F11: -0.2 | G11: 1.8 | H11: 3.1 | I11: 6.9 | J11: 0.6 | K11: 2.3 | L11: 4 | M11: 7.7 | N11: 4.9 | O11: 2.3
A12: 42552 | B12: =IFERROR(__xludf.DUMMYFUNCTION("""COMPUTED_VALUE"""),1.4333333333333333) -> 1.4333333 | D12: nov | E12: 3 | F12: 0.3 | G12: 2.1 | H12: 3 | I12: 6.1 | J12: 1.2 | K12: 3 | L12: 3.7 | M12: 8 | N12: 4.1 | O12: 2.5
A13: 42644 | B13: =IFERROR(__xludf.DUMMYFUNCTION("""COMPUTED_VALUE"""),2.0333333333333337) -> 2.0333333 | D13: dec | E13: 1.9 | F13: 0.7 | G13: 2.2 | H13: 2.9 | I13: 5.2 | J13: 2.4 | K13: 3.3 | L13: 3.1 | M13: 8.1 | N13: 3.9 | O13: 2.9
A14: 42736 | B14: =IFERROR(__xludf.DUMMYFUNCTION("""COMPUTED_VALUE"""),2.9) -> 2.9 | D14: q1 | E14: =AVERAGE(E2:E4) -> 3.6 | F14: =AVERAGE(F2:F4) -> 1.5 | G14: =AVERAGE(G2:G4) -> 0.6 | H14: =AVERAGE(H2:H4) -> 2.9 | I14: =AVERAGE(I2:I4) -> 3.8 | J14: =AVERAGE(J2:J4) -> 3.8666667 | K14: =AVERAGE(K2:K4) -> 2.5666667 | L14: =AVERAGE(L2:L4) -> 4 | ... O14: =AVERAGE(O2:O4) -> 3.3
A15: 42826 | B15: =IFERROR(__xludf.DUMMYFUNCTION("""COMPUTED_VALUE"""),2.8666666666666667) -> 2.8666667 | D15: q2 | E15: =AVERAGE(E5:E7) -> 3.8 | F15: =AVERAGE(F5:F7) -> 0.96666667 | G15: =AVERAGE(G5:G7) -> 0.96666667 | H15: =AVERAGE(H5:H7) -> 2.8666667 | I15: =AVERAGE(I5:I7) -> 4.6333333 | J15: =AVERAGE(J5:J7) -> 3.0333333 | K15: =AVERAGE(K5:K7) -> 1.9 | L15: =AVERAGE(L5:L7) -> 3.9666667 | ... O15: =AVERAGE(O5:O7) -> 3.8
A16: 42917 | B16: =IFERROR(__xludf.DUMMYFUNCTION("""COMPUTED_VALUE"""),2.6666666666666665) -> 2.6666667 | D16: q3 | E16: =AVERAGE(E8:E10) -> 4.1 | F16: =AVERAGE(F8:F10) -> -0.066666667 | G16: =AVERAGE(G8:G10) -> 1.4333333 | H16: =AVERAGE(H8:H10) -> 2.6666667 | I16: =AVERAGE(I8:I10) -> 6.4333333 | J16: =AVERAGE(J8:J10) -> 1.3666667 | K16: =AVERAGE(K8:K10) -> 2.2666667 | L16: =AVERAGE(L8:L10) -> 4.1 | ... O16: =AVERAGE(O8:O10) -> 3.2
A17: 43009 | B17: =IFERROR(__xludf.DUMMYFUNCTION("""COMPUTED_VALUE"""),3.0) -> 3 | D17: q4 | E17: =AVERAGE(E11:E13) -> 2.8666667 | F17: =AVERAGE(F11:F13) -> 0.26666667 | G17: =AVERAGE(G11:G13) -> 2.0333333 | H17: =AVERAGE(H11:H13) -> 3 | I17: =AVERAGE(I11:I13) -> 6.0666667 | J17: =AVERAGE(J11:J13) -> 1.4 | K17: =AVERAGE(K11:K13) -> 2.8666667 | L17: =AVERAGE(L11:L13) -> 3.6 | ... O17: =AVERAGE(O11:O13) -> 2.5666667
A18: 43101 | B18: =IFERROR(__xludf.DUMMYFUNCTION("""COMPUTED_VALUE"""),3.7999999999999994) -> 3.8
A19: 43191 | B19: =IFERROR(__xludf.DUMMYFUNCTION("""COMPUTED_VALUE"""),4.633333333333333) -> 4.6333333
A20: 43282 | B20: =IFERROR(__xludf.DUMMYFUNCTION("""COMPUTED_VALUE"""),6.433333333333333) -> 6.4333333
A21: 43374 | B21: =IFERROR(__xludf.DUMMYFUNCTION("""COMPUTED_VALUE"""),6.066666666666666) -> 6.0666667
A22: 43466 | B22: =IFERROR(__xludf.DUMMYFUNCTION("""COMPUTED_VALUE"""),3.8666666666666667) -> 3.8666667
A23: 43556 | B23: =IFERROR(__xludf.DUMMYFUNCTION("""COMPUTED_VALUE"""),3.0333333333333337) -> 3.0333333
A24: 43647 | B24: =IFERROR(__xludf.DUMMYFUNCTION("""COMPUTED_VALUE"""),1.3666666666666665) -> 1.3666667
A25: 43739 | B25: =IFERROR(__xludf.DUMMYFUNCTION("""COMPUTED_VALUE"""),1.3999999999999997) -> 1.4
A26: 43831 | B26: =IFERROR(__xludf.DUMMYFUNCTION("""COMPUTED_VALUE"""),2.566666666666667) -> 2.5666667
A27: 43922 | B27: =IFERROR(__xludf.DUMMYFUNCTION("""COMPUTED_VALUE"""),1.9000000000000001) -> 1.9
A28: 44013 | B28: =IFERROR(__xludf.DUMMYFUNCTION("""COMPUTED_VALUE"""),2.2666666666666666) -> 2.2666667
A29: 44105 | B29: =IFERROR(__xludf.DUMMYFUNCTION("""COMPUTED_VALUE"""),2.8666666666666667) -> 2.8666667
A30: 44197 | B30: =IFERROR(__xludf.DUMMYFUNCTION("""COMPUTED_VALUE"""),4.0) -> 4
A31: 44287 | B31: =IFERROR(__xludf.DUMMYFUNCTION("""COMPUTED_VALUE"""),3.9666666666666663) -> 3.9666667
A32: 44378 | B32: =IFERROR(__xludf.DUMMYFUNCTION("""COMPUTED_VALUE"""),4.1000000000000005) -> 4.1
A33: 44470 | B33: =IFERROR(__xludf.DUMMYFUNCTION("""COMPUTED_VALUE"""),3.6) -> 3.6
A34: 44562 | B34: =IFERROR(__xludf.DUMMYFUNCTION("""COMPUTED_VALUE"""),3.3333333333333335) -> 3.3333333
A35: 44652 | B35: =IFERROR(__xludf.DUMMYFUNCTION("""COMPUTED_VALUE"""),5.466666666666666) -> 5.4666667
A36: 44743 | B36: =IFERROR(__xludf.DUMMYFUNCTION("""COMPUTED_VALUE"""),6.533333333333334) -> 6.5333333
A37: 44835 | B37: =IFERROR(__xludf.DUMMYFUNCTION("""COMPUTED_VALUE"""),7.933333333333333) -> 7.9333333
A38: 44927 | B38: =IFERROR(__xludf.DUMMYFUNCTION("""COMPUTED_VALUE"""),8.299999999999999) -> 8.3
A39: 45017 | B39: =IFERROR(__xludf.DUMMYFUNCTION("""COMPUTED_VALUE"""),6.033333333333334) -> 6.0333333
A40: 45108 | B40: =IFERROR(__xludf.DUMMYFUNCTION("""COMPUTED_VALUE"""),5.366666666666667) -> 5.3666667
...

Sheet ex
A1: date | B1: exchange rate (average) | E1: 2014 | F1: 2015 | G1: 2016 | H1: 2017 | I1: 2018 | J1: 2019 | K1: 2020 | L1: 2021 | M1: 2022 | N1: 2023 | O1: 2024
A2: 41640 | B2: =IFERROR(__xludf.DUMMYFUNCTION("FLATTEN({E14:E17; F14:F17; G14:G17; H14:H17; I14:I17; J14:J17; K14:K17; L14:L17; M14:M17; N14:N17; O14:O17}) "),44.93566666666667) -> 44.935667 | D2: jan | E2: 45.155 | F2: 44.132 | G2: 47.823 | H2: 49.814 | I2: 51.421 | J2: 52.352 | K2: 50.904 | L2: 48.121 | M2: 51.273 | N2: 54.545 | O2: 56.335
A3: 41730 | B3: =IFERROR(__xludf.DUMMYFUNCTION("""COMPUTED_VALUE"""),44.05666666666667) -> 44.056667 | D3: feb | E3: 44.656 | F3: 44.087 | G3: 47.56 | H3: 50.267 | I3: 52.034 | J3: 52.006 | K3: 50.937 | L3: 48.637 | M3: 51.291 | N3: 55.312 | O3: 56.187
A4: 41821 | B4: =IFERROR(__xludf.DUMMYFUNCTION("""COMPUTED_VALUE"""),44.01166666666666) -> 44.011667 | D4: mar | E4: 44.996 | F4: 44.796 | G4: 46.108 | H4: 50.194 | I4: 52.207 | J4: 52.782 | K4: 51.044 | L4: 48.466 | M4: 51.96 | N4: 54.429 | O4: 56.281
A5: 41913 | B5: =IFERROR(__xludf.DUMMYFUNCTION("""COMPUTED_VALUE"""),44.803) -> 44.803 | D5: apr | E5: 44.463 | F5: 44.25 | G5: 46.773 | H5: 49.699 | I5: 51.965 | J5: 52.106 | K5: 50.589 | L5: 48.39 | M5: 52.158 | N5: 55.742 | O5: 57.697
A6: 42005 | B6: =IFERROR(__xludf.DUMMYFUNCTION("""COMPUTED_VALUE"""),44.33833333333333) -> 44.338333 | D6: may | E6: 43.927 | F6: 44.65 | G6: 46.775 | H6: 49.867 | I6: 52.689 | J6: 52.257 | K6: 50.727 | L6: 47.901 | M6: 52.243 | N6: 56.26 | O6: 58.62
A7: 42095 | B7: =IFERROR(__xludf.DUMMYFUNCTION("""COMPUTED_VALUE"""),44.70000000000001) -> 44.7 | D7: jun | E7: 43.78 | F7: 45.2 | G7: 46.96 | H7: 50.466 | I7: 53.522 | J7: 51.358 | K7: 49.851 | L7: 48.544 | M7: 55.021 | N7: 55.362 | O7: 58.868
A8: 42186 | B8: =IFERROR(__xludf.DUMMYFUNCTION("""COMPUTED_VALUE"""),46.41633333333334) -> 46.416333 | D8: jul | E8: 43.421 | F8: 45.618 | G8: 47.085 | H8: 50.582 | I8: 53.263 | J8: 51.013 | K8: 49.217 | L8: 50.342 | M8: 55.722 | N8: 54.847 | O8: 58.645
A9: 42278 | B9: =IFERROR(__xludf.DUMMYFUNCTION("""COMPUTED_VALUE"""),47.041666666666664) -> 47.041667 | D9: aug | E9: 43.648 | F9: 46.705 | G9: 46.467 | H9: 51.166 | I9: 53.434 | J9: 52.339 | K9: 48.621 | L9: 50.04 | M9: 56.243 | N9: 56.702 | O9: 56.289
A10: 42370 | B10: =IFERROR(__xludf.DUMMYFUNCTION("""COMPUTED_VALUE"""),47.16366666666667) -> 47.163667 | D10: sep | E10: 44.966 | F10: 46.926 | G10: 48.257 | H10: 51.073 | I10: 54.251 | J10: 52.042 | K10: 48.465 | L10: 50.959 | M10: 58.91 | N10: 56.961 | O10: 55.892
A11: 42461 | B11: =IFERROR(__xludf.DUMMYFUNCTION("""COMPUTED_VALUE"""),46.836000000000006) -> 46.836 | D11: oct | E11: 44.876 | F11: 46.89 | G11: 48.515 | H11: 51.799 | I11: 53.606 | J11: 51.033 | K11: 48.401 | L11: 50.77 | M11: 58.288 | N11: 56.903 | O11: 58.254
A12: 42552 | B12: =IFERROR(__xludf.DUMMYFUNCTION("""COMPUTED_VALUE"""),47.269666666666666) -> 47.269667 | D12: nov | E12: 44.916 | F12: 47.069 | G12: 49.777 | H12: 50.365 | I12: 52.608 | J12: 50.798 | K12: 48.102 | L12: 50.458 | M12: 56.796 | N12: 55.328 | O12: 58.694
A13: 42644 | B13: =IFERROR(__xludf.DUMMYFUNCTION("""COMPUTED_VALUE"""),49.36833333333334) -> 49.368333 | D13: dec | E13: 44.617 | F13: 47.166 | G13: 49.813 | H13: 49.923 | I13: 52.724 | J13: 50.744 | K13: 48.036 | L13: 50.774 | M13: 56.12 | N13: 55.567 | O13: 58.014
A14: 42736 | B14: =IFERROR(__xludf.DUMMYFUNCTION("""COMPUTED_VALUE"""),50.09166666666667) -> 50.091667 | D14: q1 | E14: =AVERAGE(E2:E4) -> 44.935667 | F14: =AVERAGE(F2:F4) -> 44.338333 | G14: =AVERAGE(G2:G4) -> 47.163667 | H14: =AVERAGE(H2:H4) -> 50.091667 | I14: =AVERAGE(I2:I4) -> 51.887333 | J14: =AVERAGE(J2:J4) -> 52.38 | K14: =AVERAGE(K2:K4) -> 50.961667 | L14: =AVERAGE(L2:L4) -> 48.408 | ... O14: =AVERAGE(O2:O4) -> 56.267667
A15: 42826 | B15: =IFERROR(__xludf.DUMMYFUNCTION("""COMPUTED_VALUE"""),50.01066666666667) -> 50.010667 | D15: q2 | E15: =AVERAGE(E5:E7) -> 44.056667 | F15: =AVERAGE(F5:F7) -> 44.7 | G15: =AVERAGE(G5:G7) -> 46.836 | H15: =AVERAGE(H5:H7) -> 50.010667 | I15: =AVERAGE(I5:I7) -> 52.725333 | J15: =AVERAGE(J5:J7) -> 51.907 | K15: =AVERAGE(K5:K7) -> 50.389 | L15: =AVERAGE(L5:L7) -> 48.278333 | ... O15: =AVERAGE(O5:O7) -> 58.395
A16: 42917 | B16: =IFERROR(__xludf.DUMMYFUNCTION("""COMPUTED_VALUE"""),50.940333333333335) -> 50.940333 | D16: q3 | E16: =AVERAGE(E8:E10) -> 44.011667 | F16: =AVERAGE(F8:F10) -> 46.416333 | G16: =AVERAGE(G8:G10) -> 47.269667 | H16: =AVERAGE(H8:H10) -> 50.940333 | I16: =AVERAGE(I8:I10) -> 53.649333 | J16: =AVERAGE(J8:J10) -> 51.798 | K16: =AVERAGE(K8:K10) -> 48.767667 | L16: =AVERAGE(L8:L10) -> 50.447 | ... O16: =AVERAGE(O8:O10) -> 56.942
A17: 43009 | B17: =IFERROR(__xludf.DUMMYFUNCTION("""COMPUTED_VALUE"""),50.69566666666666) -> 50.695667 | D17: q4 | E17: =AVERAGE(E11:E13) -> 44.803 | F17: =AVERAGE(F11:F13) -> 47.041667 | G17: =AVERAGE(G11:G13) -> 49.368333 | H17: =AVERAGE(H11:H13) -> 50.695667 | I17: =AVERAGE(I11:I13) -> 52.979333 | J17: =AVERAGE(J11:J13) -> 50.858333 | K17: =AVERAGE(K11:K13) -> 48.179667 | L17: =AVERAGE(L11:L13) -> 50.667333 | ... O17: =AVERAGE(O11:O13) -> 58.320667
A18: 43101 | B18: =IFERROR(__xludf.DUMMYFUNCTION("""COMPUTED_VALUE"""),51.88733333333334) -> 51.887333
A19: 43191 | B19: =IFERROR(__xludf.DUMMYFUNCTION("""COMPUTED_VALUE"""),52.72533333333333) -> 52.725333
A20: 43282 | B20: =IFERROR(__xludf.DUMMYFUNCTION("""COMPUTED_VALUE"""),53.64933333333334) -> 53.649333
A21: 43374 | B21: =IFERROR(__xludf.DUMMYFUNCTION("""COMPUTED_VALUE"""),52.97933333333333) -> 52.979333
A22: 43466 | B22: =IFERROR(__xludf.DUMMYFUNCTION("""COMPUTED_VALUE"""),52.379999999999995) -> 52.38
A23: 43556 | B23: =IFERROR(__xludf.DUMMYFUNCTION("""COMPUTED_VALUE"""),51.907000000000004) -> 51.907
A24: 43647 | B24: =IFERROR(__xludf.DUMMYFUNCTION("""COMPUTED_VALUE"""),51.798) -> 51.798
A25: 43739 | B25: =IFERROR(__xludf.DUMMYFUNCTION("""COMPUTED_VALUE"""),50.85833333333333) -> 50.858333
A26: 43831 | B26: =IFERROR(__xludf.DUMMYFUNCTION("""COMPUTED_VALUE"""),50.961666666666666) -> 50.961667
A27: 43922 | B27: =IFERROR(__xludf.DUMMYFUNCTION("""COMPUTED_VALUE"""),50.389) -> 50.389
A28: 44013 | B28: =IFERROR(__xludf.DUMMYFUNCTION("""COMPUTED_VALUE"""),48.76766666666666) -> 48.767667
A29: 44105 | B29: =IFERROR(__xludf.DUMMYFUNCTION("""COMPUTED_VALUE"""),48.17966666666666) -> 48.179667
A30: 44197 | B30: =IFERROR(__xludf.DUMMYFUNCTION("""COMPUTED_VALUE"""),48.40800000000001) -> 48.408
A31: 44287 | B31: =IFERROR(__xludf.DUMMYFUNCTION("""COMPUTED_VALUE"""),48.27833333333333) -> 48.278333
A32: 44378 | B32: =IFERROR(__xludf.DUMMYFUNCTION("""COMPUTED_VALUE"""),50.447) -> 50.447
A33: 44470 | B33: =IFERROR(__xludf.DUMMYFUNCTION("""COMPUTED_VALUE"""),50.66733333333334) -> 50.667333
A34: 44562 | B34: =IFERROR(__xludf.DUMMYFUNCTION("""COMPUTED_VALUE"""),51.508) -> 51.508
A35: 44652 | B35: =IFERROR(__xludf.DUMMYFUNCTION("""COMPUTED_VALUE"""),53.140666666666675) -> 53.140667
A36: 44743 | B36: =IFERROR(__xludf.DUMMYFUNCTION("""COMPUTED_VALUE"""),56.958333333333336) -> 56.958333
A37: 44835 | B37: =IFERROR(__xludf.DUMMYFUNCTION("""COMPUTED_VALUE"""),57.068000000000005) -> 57.068
A38: 44927 | B38: =IFERROR(__xludf.DUMMYFUNCTION("""COMPUTED_VALUE"""),54.762) -> 54.762
A39: 45017 | B39: =IFERROR(__xludf.DUMMYFUNCTION("""COMPUTED_VALUE"""),55.788000000000004) -> 55.788
A40: 45108 | B40: =IFERROR(__xludf.DUMMYFUNCTION("""COMPUTED_VALUE"""),56.169999999999995) -> 56.17
...

Sheet int
A1: date | B1: Savings Deposit Rate (average) | E1: 2014 | F1: 2015 | G1: 2016 | H1: 2017 | I1: 2018 | J1: 2019 | K1: 2020 | L1: 2021 | M1: 2022 | N1: 2023 | O1: 2024
A2: 41640 | B2: =IFERROR(__xludf.DUMMYFUNCTION("FLATTEN({E14:E17; F14:F17; G14:G17; H14:H17; I14:I17; J14:J17; K14:K17; L14:L17; M14:M17; N14:N17; O14:O17}) "),0.5373333333333333) -> 0.53733333 | D2: jan | E2: 0.549 | F2: 0.794 | G2: 0.794 | H2: 0.738 | I2: 0.798 | J2: 1.403 | K2: 0.317 | L2: 0.198 | M2: 0.404 | N2: 1.187 | O2: 1.671
A3: 41730 | B3: =IFERROR(__xludf.DUMMYFUNCTION("""COMPUTED_VALUE"""),0.6276666666666667) -> 0.62766667 | D3: feb | E3: 0.501 | F3: 0.703 | G3: 0.703 | H3: 0.635 | I3: 0.67 | J3: 1.239 | K3: 0.323 | L3: 0.211 | M3: 0.355 | N3: 1.24 | O3: 1.649
A4: 41821 | B4: =IFERROR(__xludf.DUMMYFUNCTION("""COMPUTED_VALUE"""),0.6463333333333333) -> 0.64633333 | D4: mar | E4: 0.562 | F4: 0.655 | G4: 0.655 | H4: 0.693 | I4: 0.758 | J4: 1.409 | K4: 0.435 | L4: 0.213 | M4: 0.401 | N4: 1.444 | O4: 1.733
A5: 41913 | B5: =IFERROR(__xludf.DUMMYFUNCTION("""COMPUTED_VALUE"""),0.7026666666666667) -> 0.70266667 | D5: apr | E5: 0.632 | F5: 0.682 | G5: 0.682 | H5: 0.67 | I5: 0.747 | J5: 1.326 | K5: 0.395 | L5: 0.239 | M5: 0.382 | N5: 1.481 | O5: 1.673
A6: 42005 | B6: =IFERROR(__xludf.DUMMYFUNCTION("""COMPUTED_VALUE"""),0.7173333333333334) -> 0.71733333 | D6: may | E6: 0.626 | F6: 0.678 | G6: 0.678 | H6: 0.679 | I6: 0.811 | J6: 1.358 | K6: 0.415 | L6: 0.26 | M6: 0.403 | N6: 1.6 | O6: 1.989
A7: 42095 | B7: =IFERROR(__xludf.DUMMYFUNCTION("""COMPUTED_VALUE"""),0.672) -> 0.672 | D7: jun | E7: 0.625 | F7: 0.656 | G7: 0.656 | H7: 0.647 | I7: 0.795 | J7: 1.244 | K7: 0.35 | L7: 0.151 | M7: 0.43 | N7: 1.561 | O7: 1.757
A8: 42186 | B8: =IFERROR(__xludf.DUMMYFUNCTION("""COMPUTED_VALUE"""),0.7213333333333334) -> 0.72133333 | D8: jul | E8: 0.67 | F8: 0.741 | G8: 0.741 | H8: 0.707 | I8: 0.877 | J8: 1.365 | K8: 0.373 | L8: 0.234 | M8: 0.506 | N8: 1.754 | O8: 1.995
A9: 42278 | B9: =IFERROR(__xludf.DUMMYFUNCTION("""COMPUTED_VALUE"""),0.7273333333333333) -> 0.72733333 | D9: aug | E9: 0.645 | F9: 0.738 | G9: 0.738 | H9: 0.713 | I9: 0.896 | J9: 1.341 | K9: 0.364 | L9: 0.23 | M9: 0.586 | N9: 1.83 | O9: 2.008
A10: 42370 | B10: =IFERROR(__xludf.DUMMYFUNCTION("""COMPUTED_VALUE"""),0.7173333333333334) -> 0.71733333 | D10: sep | E10: 0.624 | F10: 0.685 | G10: 0.685 | H10: 0.674 | I10: 0.983 | J10: 1.13 | K10: 0.427 | L10: 0.434 | M10: 0.748 | N10: 1.657 | O10: 1.896
A11: 42461 | B11: =IFERROR(__xludf.DUMMYFUNCTION("""COMPUTED_VALUE"""),0.672) -> 0.672 | D11: oct | E11: 0.675 | F11: 0.737 | G11: 0.737 | H11: 0.704 | I11: 1.081 | J11: 0.994 | K11: 0.338 | L11: 0.444 | M11: 0.901 | N11: 1.887 | O11: 1.947
A12: 42552 | B12: =IFERROR(__xludf.DUMMYFUNCTION("""COMPUTED_VALUE"""),0.7213333333333334) -> 0.72133333 | D12: nov | E12: 0.683 | F12: 0.707 | G12: 0.707 | H12: 0.651 | I12: 1.126 | J12: 0.999 | K12: 0.314 | L12: 0.434 | M12: 1.042 | N12: 1.645 | O12: 1.899
A13: 42644 | B13: =IFERROR(__xludf.DUMMYFUNCTION("""COMPUTED_VALUE"""),0.7273333333333333) -> 0.72733333 | D13: dec | E13: 0.75 | F13: 0.738 | G13: 0.738 | H13: 0.709 | I13: 1.196 | J13: 0.974 | K13: 0.279 | L13: 0.446 | M13: 1.199 | N13: 1.719 | O13: 1.801
A14: 42736 | B14: =IFERROR(__xludf.DUMMYFUNCTION("""COMPUTED_VALUE"""),0.6886666666666666) -> 0.68866667 | D14: q1 | E14: =AVERAGE(E2:E4) -> 0.53733333 | F14: =AVERAGE(F2:F4) -> 0.71733333 | G14: =AVERAGE(G2:G4) -> 0.71733333 | H14: =AVERAGE(H2:H4) -> 0.68866667 | I14: =AVERAGE(I2:I4) -> 0.742 | J14: =AVERAGE(J2:J4) -> 1.3503333 | K14: =AVERAGE(K2:K4) -> 0.35833333 | L14: =AVERAGE(L2:L4) -> 0.20733333 | ... O14: =AVERAGE(O2:O4) -> 1.6843333
A15: 42826 | B15: =IFERROR(__xludf.DUMMYFUNCTION("""COMPUTED_VALUE"""),0.6653333333333334) -> 0.66533333 | D15: q2 | E15: =AVERAGE(E5:E7) -> 0.62766667 | F15: =AVERAGE(F5:F7) -> 0.672 | G15: =AVERAGE(G5:G7) -> 0.672 | H15: =AVERAGE(H5:H7) -> 0.66533333 | I15: =AVERAGE(I5:I7) -> 0.78433333 | J15: =AVERAGE(J5:J7) -> 1.3093333 | K15: =AVERAGE(K5:K7) -> 0.38666667 | L15: =AVERAGE(L5:L7) -> 0.21666667 | ... O15: =AVERAGE(O5:O7) -> 1.8063333
A16: 42917 | B16: =IFERROR(__xludf.DUMMYFUNCTION("""COMPUTED_VALUE"""),0.698) -> 0.698 | D16: q3 | E16: =AVERAGE(E8:E10) -> 0.64633333 | F16: =AVERAGE(F8:F10) -> 0.72133333 | G16: =AVERAGE(G8:G10) -> 0.72133333 | H16: =AVERAGE(H8:H10) -> 0.698 | I16: =AVERAGE(I8:I10) -> 0.91866667 | J16: =AVERAGE(J8:J10) -> 1.2786667 | K16: =AVERAGE(K8:K10) -> 0.388 | L16: =AVERAGE(L8:L10) -> 0.29933333 | ... O16: =AVERAGE(O8:O10) -> 1.9663333
A17: 43009 | B17: =IFERROR(__xludf.DUMMYFUNCTION("""COMPUTED_VALUE"""),0.6880000000000001) -> 0.688 | D17: q4 | E17: =AVERAGE(E11:E13) -> 0.70266667 | F17: =AVERAGE(F11:F13) -> 0.72733333 | G17: =AVERAGE(G11:G13) -> 0.72733333 | H17: =AVERAGE(H11:H13) -> 0.688 | I17: =AVERAGE(I11:I13) -> 1.1343333 | J17: =AVERAGE(J11:J13) -> 0.989 | K17: =AVERAGE(K11:K13) -> 0.31033333 | L17: =AVERAGE(L11:L13) -> 0.44133333 | ... O17: =AVERAGE(O11:O13) -> 1.8823333
A18: 43101 | B18: =IFERROR(__xludf.DUMMYFUNCTION("""COMPUTED_VALUE"""),0.742) -> 0.742
A19: 43191 | B19: =IFERROR(__xludf.DUMMYFUNCTION("""COMPUTED_VALUE"""),0.7843333333333334) -> 0.78433333
A20: 43282 | B20: =IFERROR(__xludf.DUMMYFUNCTION("""COMPUTED_VALUE"""),0.9186666666666667) -> 0.91866667
A21: 43374 | B21: =IFERROR(__xludf.DUMMYFUNCTION("""COMPUTED_VALUE"""),1.1343333333333332) -> 1.1343333
A22: 43466 | B22: =IFERROR(__xludf.DUMMYFUNCTION("""COMPUTED_VALUE"""),1.3503333333333334) -> 1.3503333
A23: 43556 | B23: =IFERROR(__xludf.DUMMYFUNCTION("""COMPUTED_VALUE"""),1.3093333333333332) -> 1.3093333
A24: 43647 | B24: =IFERROR(__xludf.DUMMYFUNCTION("""COMPUTED_VALUE"""),1.2786666666666666) -> 1.2786667
A25: 43739 | B25: =IFERROR(__xludf.DUMMYFUNCTION("""COMPUTED_VALUE"""),0.9889999999999999) -> 0.989
A26: 43831 | B26: =IFERROR(__xludf.DUMMYFUNCTION("""COMPUTED_VALUE"""),0.35833333333333334) -> 0.35833333
A27: 43922 | B27: =IFERROR(__xludf.DUMMYFUNCTION("""COMPUTED_VALUE"""),0.3866666666666667) -> 0.38666667
A28: 44013 | B28: =IFERROR(__xludf.DUMMYFUNCTION("""COMPUTED_VALUE"""),0.38799999999999996) -> 0.388
A29: 44105 | B29: =IFERROR(__xludf.DUMMYFUNCTION("""COMPUTED_VALUE"""),0.31033333333333335) -> 0.31033333
A30: 44197 | B30: =IFERROR(__xludf.DUMMYFUNCTION("""COMPUTED_VALUE"""),0.20733333333333334) -> 0.20733333
A31: 44287 | B31: =IFERROR(__xludf.DUMMYFUNCTION("""COMPUTED_VALUE"""),0.21666666666666667) -> 0.21666667
A32: 44378 | B32: =IFERROR(__xludf.DUMMYFUNCTION("""COMPUTED_VALUE"""),0.29933333333333334) -> 0.29933333
A33: 44470 | B33: =IFERROR(__xludf.DUMMYFUNCTION("""COMPUTED_VALUE"""),0.44133333333333336) -> 0.44133333
A34: 44562 | B34: =IFERROR(__xludf.DUMMYFUNCTION("""COMPUTED_VALUE"""),0.3866666666666667) -> 0.38666667
A35: 44652 | B35: =IFERROR(__xludf.DUMMYFUNCTION("""COMPUTED_VALUE"""),0.405) -> 0.405
A36: 44743 | B36: =IFERROR(__xludf.DUMMYFUNCTION("""COMPUTED_VALUE"""),0.6133333333333334) -> 0.61333333
A37: 44835 | B37: =IFERROR(__xludf.DUMMYFUNCTION("""COMPUTED_VALUE"""),1.0473333333333334) -> 1.0473333
A38: 44927 | B38: =IFERROR(__xludf.DUMMYFUNCTION("""COMPUTED_VALUE"""),1.2903333333333333) -> 1.2903333
A39: 45017 | B39: =IFERROR(__xludf.DUMMYFUNCTION("""COMPUTED_VALUE"""),1.5473333333333334) -> 1.5473333
A40: 45108 | B40: =IFERROR(__xludf.DUMMYFUNCTION("""COMPUTED_VALUE"""),1.7469999999999999) -> 1.747
...

Sheet unem
A1: date | B1: unemployment rate (average) | E1: 2014 | F1: 2015 | G1: 2016 | H1: 2017 | I1: 2018 | J1: 2019 | K1: 2020 | L1: 2021 | M1: 2022 | N1: 2023 | O1: 2024
A2: 41640 | B2: =IFERROR(__xludf.DUMMYFUNCTION("FLATTEN({E14:E17; F14:F17; G14:G17; H14:H17; I14:I17; J14:J17; K14:K17; L14:L17; M14:M17; N14:N17; O14:O17})"),7.5) -> 7.5 | D2: jan | L2: 8.8 | M2: 6.4 | N2: 4.8 | O2: 4.5
A3: 41730 | B3: =IFERROR(__xludf.DUMMYFUNCTION("""COMPUTED_VALUE"""),7.0) -> 7 | D3: feb | L3: 8.8 | M3: 6.4 | N3: 4.8 | O3: 3.5
A4: 41821 | B4: =IFERROR(__xludf.DUMMYFUNCTION("""COMPUTED_VALUE"""),6.7) -> 6.7 | D4: mar | L4: 7.1 | M4: 5.8 | N4: 4.7 | O4: 3.9
A5: 41913 | B5: =IFERROR(__xludf.DUMMYFUNCTION("""COMPUTED_VALUE"""),6.0) -> 6 | D5: apr | L5: 8.7 | M5: 5.7 | N5: 4.5 | O5: 4
A6: 42005 | B6: =IFERROR(__xludf.DUMMYFUNCTION("""COMPUTED_VALUE"""),6.6) -> 6.6 | D6: may | L6: 7.7 | M6: 6 | N6: 4.3 | O6: 4.1
A7: 42095 | B7: =IFERROR(__xludf.DUMMYFUNCTION("""COMPUTED_VALUE"""),6.4) -> 6.4 | D7: jun | L7: 7.7 | M7: 6 | N7: 4.5 | O7: 3.1
A8: 42186 | B8: =IFERROR(__xludf.DUMMYFUNCTION("""COMPUTED_VALUE"""),6.5) -> 6.5 | D8: jul | L8: 7.2 | M8: 5.2 | N8: 4.9 | O8: 4.7
A9: 42278 | B9: =IFERROR(__xludf.DUMMYFUNCTION("""COMPUTED_VALUE"""),5.7) -> 5.7 | D9: aug | L9: 8.1 | M9: 5.3 | N9: 4.4 | O9: 4
A10: 42370 | B10: =IFERROR(__xludf.DUMMYFUNCTION("""COMPUTED_VALUE"""),5.8) -> 5.8 | D10: sep | L10: 8.9 | M10: 5 | N10: 4.5 | O10: 3.7
A11: 42461 | B11: =IFERROR(__xludf.DUMMYFUNCTION("""COMPUTED_VALUE"""),6.1) -> 6.1 | D11: oct | L11: 7.4 | M11: 4.5 | N11: 4.2 | O11: 3.9
A12: 42552 | B12: =IFERROR(__xludf.DUMMYFUNCTION("""COMPUTED_VALUE"""),5.4) -> 5.4 | D12: nov | L12: 6.5 | M12: 4.2 | N12: 3.6 | O12: 3.2
A13: 42644 | B13: =IFERROR(__xludf.DUMMYFUNCTION("""COMPUTED_VALUE"""),4.7) -> 4.7 | D13: dec | L13: 6.6 | M13: 4.3 | N13: 3.1 | O13: 3.1
A14: 42736 | B14: =IFERROR(__xludf.DUMMYFUNCTION("""COMPUTED_VALUE"""),6.6) -> 6.6 | D14: q1 | E14: 7.5 | F14: 6.6 | G14: 5.8 | H14: 6.6 | I14: 5.3 | J14: 5.2 | K14: 5.3 | L14: =AVERAGE(L2:L4) -> 8.2333333 | M14: =AVERAGE(M2:M4) -> 6.2 | N14: =AVERAGE(N2:N4) -> 4.7666667 | O14: =AVERAGE(O2:O4) -> 3.9666667
A15: 42826 | B15: =IFERROR(__xludf.DUMMYFUNCTION("""COMPUTED_VALUE"""),5.7) -> 5.7 | D15: q2 | E15: 7 | F15: 6.4 | G15: 6.1 | H15: 5.7 | I15: 5.5 | J15: 5.1 | K15: 17.6 | L15: =AVERAGE(L5:L7) -> 8.0333333 | M15: =AVERAGE(M5:M7) -> 5.9 | N15: =AVERAGE(N5:N7) -> 4.4333333 | O15: =AVERAGE(O5:O7) -> 3.7333333
A16: 42917 | B16: =IFERROR(__xludf.DUMMYFUNCTION("""COMPUTED_VALUE"""),5.6) -> 5.6 | D16: q3 | E16: 6.7 | F16: 6.5 | G16: 5.4 | H16: 5.6 | I16: 5.4 | J16: 5.4 | K16: 10 | L16: =AVERAGE(L8:L10) -> 8.0666667 | M16: =AVERAGE(M8:M10) -> 5.1666667 | N16: =AVERAGE(N8:N10) -> 4.6 | O16: =AVERAGE(O8:O10) -> 4.1333333
A17: 43009 | B17: =IFERROR(__xludf.DUMMYFUNCTION("""COMPUTED_VALUE"""),5.0) -> 5 | D17: q4 | E17: 6 | F17: 5.7 | G17: 4.7 | H17: 5 | I17: 5.1 | J17: 4.5 | K17: 8.7 | L17: =AVERAGE(L11:L13) -> 6.8333333 | M17: =AVERAGE(M11:M13) -> 4.3333333 | N17: =AVERAGE(N11:N13) -> 3.6333333 | O17: =AVERAGE(O11:O13) -> 3.4
A18: 43101 | B18: =IFERROR(__xludf.DUMMYFUNCTION("""COMPUTED_VALUE"""),5.3) -> 5.3
A19: 43191 | B19: =IFERROR(__xludf.DUMMYFUNCTION("""COMPUTED_VALUE"""),5.5) -> 5.5
A20: 43282 | B20: =IFERROR(__xludf.DUMMYFUNCTION("""COMPUTED_VALUE"""),5.4) -> 5.4
A21: 43374 | B21: =IFERROR(__xludf.DUMMYFUNCTION("""COMPUTED_VALUE"""),5.1) -> 5.1
A22: 43466 | B22: =IFERROR(__xludf.DUMMYFUNCTION("""COMPUTED_VALUE"""),5.2) -> 5.2
A23: 43556 | B23: =IFERROR(__xludf.DUMMYFUNCTION("""COMPUTED_VALUE"""),5.1) -> 5.1
A24: 43647 | B24: =IFERROR(__xludf.DUMMYFUNCTION("""COMPUTED_VALUE"""),5.4) -> 5.4
A25: 43739 | B25: =IFERROR(__xludf.DUMMYFUNCTION("""COMPUTED_VALUE"""),4.5) -> 4.5
A26: 43831 | B26: =IFERROR(__xludf.DUMMYFUNCTION("""COMPUTED_VALUE"""),5.3) -> 5.3
A27: 43922 | B27: =IFERROR(__xludf.DUMMYFUNCTION("""COMPUTED_VALUE"""),17.6) -> 17.6
A28: 44013 | B28: =IFERROR(__xludf.DUMMYFUNCTION("""COMPUTED_VALUE"""),10.0) -> 10
A29: 44105 | B29: =IFERROR(__xludf.DUMMYFUNCTION("""COMPUTED_VALUE"""),8.7) -> 8.7
A30: 44197 | B30: =IFERROR(__xludf.DUMMYFUNCTION("""COMPUTED_VALUE"""),8.233333333333334) -> 8.2333333
A31: 44287 | B31: =IFERROR(__xludf.DUMMYFUNCTION("""COMPUTED_VALUE"""),8.033333333333333) -> 8.0333333
A32: 44378 | B32: =IFERROR(__xludf.DUMMYFUNCTION("""COMPUTED_VALUE"""),8.066666666666668) -> 8.0666667
A33: 44470 | B33: =IFERROR(__xludf.DUMMYFUNCTION("""COMPUTED_VALUE"""),6.833333333333333) -> 6.8333333
A34: 44562 | B34: =IFERROR(__xludf.DUMMYFUNCTION("""COMPUTED_VALUE"""),6.2) -> 6.2
A35: 44652 | B35: =IFERROR(__xludf.DUMMYFUNCTION("""COMPUTED_VALUE"""),5.8999999999999995) -> 5.9
A36: 44743 | B36: =IFERROR(__xludf.DUMMYFUNCTION("""COMPUTED_VALUE"""),5.166666666666667) -> 5.1666667
A37: 44835 | B37: =IFERROR(__xludf.DUMMYFUNCTION("""COMPUTED_VALUE"""),4.333333333333333) -> 4.3333333
A38: 44927 | B38: =IFERROR(__xludf.DUMMYFUNCTION("""COMPUTED_VALUE"""),4.766666666666667) -> 4.7666667
A39: 45017 | B39: =IFERROR(__xludf.DUMMYFUNCTION("""COMPUTED_VALUE"""),4.433333333333334) -> 4.4333333
A40: 45108 | B40: =IFERROR(__xludf.DUMMYFUNCTION("""COMPUTED_VALUE"""),4.6000000000000005) -> 4.6
...

Sheet ggrowth
A1: date | B1: gdp growth rate (in percent)
A2: 41640 | B2: {=TRANSPOSE(D2:AU2)} -> 9.5 | D2: 9.5 | E2: 10.1 | F2: 8.9 | G2: 9.8 | H2: 5.5 | I2: 6 | J2: 4.9 | K2: 5.8 | L2: 7.3 | M2: 8.5 | N2: 9.4 | O2: 8.8 | P2: 9 | Q2: 9.6 | R2: 10.2 | S2: 8.9 | T2: 9.5 | U2: 10 | V2: 10.8 | W2: 10.9 | X2: 7.9 | Y2: 6.5 | Z2: 6.2 | AA2: 6.9 | AB2: 0.5 | AC2: -15 | AD2: -11 | AE2: -6.2 | AF2: -1.7 | AG2: 15.2 | AH2: 9.5 | AI2: 9.8 | AJ2: 12.7 | AK2: 13.2 | AL2: 14 | AM2: 13.9 | AN2: 13.9 | AO2: 9.1 | AP2: 9.7 | AQ2: 9.3 | AR2: 9 | AS2: 10.3 | AT2: 8.6 | AU2: 7.5
A3: 41730 | B3: 10.1
A4: 41821 | B4: 8.9
A5: 41913 | B5: 9.8
A6: 42005 | B6: 5.5
A7: 42095 | B7: 6
A8: 42186 | B8: 4.9
A9: 42278 | B9: 5.8
A10: 42370 | B10: 7.3
A11: 42461 | B11: 8.5
A12: 42552 | B12: 9.4
A13: 42644 | B13: 8.8
A14: 42736 | B14: 9
... A45: 45566 | B45: 7.5

Sheet philippines_typhoon_monthly_201
A1: Year | B1: Month | C1: Number_of_Typhoons | D1: ONI | E1: Nino3.4_SST_anomaly | F1: Western_Pacific_SST | G1: Vertical_Wind_Shear | H1: Midlevel_Humidity | I1: SeaLevelPressure | J1: MJO_Phase | K1: Prev_month_typhoons | M1: date | N1: typhoons (sum)
A2: 2014 | B2: 1 | C2: 1 | D2: 0.03 | E2: -0.05 | F2: 0.36 | G2: 13.2 | H2: 54.8 | I2: 1009.8 | J2: 0 | K2: 0 | M2: 41640 | N2: =SUM(C2:C4) -> 1
A3: 2014 | B3: 2 | C3: 0 | D3: 0.2 | E3: 0.18 | F3: -0.43 | G3: 13.8 | H3: 59.5 | I3: 1009.5 | J3: 7 | K3: 1
A4: 2014 | B4: 3 | C4: 0 | D4: 0.02 | E4: 0 | F4: 0.01 | G4: 13 | H4: 49.3 | I4: 1009.4 | J4: 6 | K4: 0
A5: 2014 | B5: 4 | C5: 0 | D5: 0.13 | E5: 0.07 | F5: -0.15 | G5: 10.7 | H5: 57.8 | I5: 1008.2 | J5: 0 | K5: 0 | M5: 41730 | N5: =SUM(C5:C7) -> 3
A6: 2014 | B6: 5 | C6: 0 | D6: -0.03 | E6: -0.05 | F6: -0.41 | G6: 11.1 | H6: 61.4 | I6: 1008.1 | J6: 3 | K6: 0
A7: 2014 | B7: 6 | C7: 3 | D7: 0.19 | E7: 0.12 | F7: 0.02 | G7: 8 | H7: 69.6 | I7: 1006.3 | J7: 1 | K7: 0
A8: 2014 | B8: 7 | C8: 3 | D8: 0.17 | E8: 0.13 | F8: 0.55 | G8: 9 | H8: 70.4 | I8: 1006.4 | J8: 8 | K8: 3 | M8: 41821 | N8: =SUM(C8:C10) -> 7
A9: 2014 | B9: 8 | C9: 2 | D9: 0.12 | E9: 0.05 | F9: 0.13 | G9: 8 | H9: 70 | I9: 1005.2 | J9: 5 | K9: 3
A10: 2014 | B10: 9 | C10: 2 | D10: -0.11 | E10: -0.05 | F10: 0.33 | G10: 6.9 | H10: 73.1 | I10: 1004.7 | J10: 3 | K10: 2
A11: 2014 | B11: 10 | C11: 4 | D11: -0.01 | E11: 0.07 | F11: -0.32 | G11: 9.4 | H11: 60.7 | I11: 1004.6 | J11: 8 | K11: 2 | M11: 41913 | N11: =SUM(C11:C13) -> 5
A12: 2014 | B12: 11 | C12: 1 | D12: -0.01 | E12: 0.04 | F12: -0.27 | G12: 10.4 | H12: 63.3 | I12: 1009.5 | J12: 1 | K12: 4
A13: 2014 | B13: 12 | C13: 0 | D13: 0.06 | E13: 0.08 | F13: -0.09 | G13: 11.8 | H13: 61.4 | I13: 1011.1 | J13: 5 | K13: 1
A14: 2015 | B14: 1 | C14: 0 | D14: 1.52 | E14: 1.55 | F14: -0.08 | G14: 11.9 | H14: 60.4 | I14: 1009.2 | J14: 3 | K14: 0 | M14: 42005 | N14: =SUM(C14:C16) -> 1
A15: 2015 | B15: 2 | C15: 1 | D15: 1.4 | E15: 1.46 | F15: 0.55 | G15: 12.3 | H15: 58.1 | I15: 1009.6 | J15: 3 | K15: 0
A16: 2015 | B16: 3 | C16: 0 | D16: 1.48 | E16: 1.41 | F16: 0.16 | G16: 12.9 | H16: 53.3 | I16: 1010.1 | J16: 5 | K16: 1
A17: 2015 | B17: 4 | C17: 0 | D17: 1.57 | E17: 1.63 | F17: 0 | G17: 9.4 | H17: 58 | I17: 1006.9 | J17: 3 | K17: 0 | M17: 42095 | N17: =SUM(C17:C19) -> 1
A18: 2015 | B18: 5 | C18: 1 | D18: 1.61 | E18: 1.54 | F18: -0.37 | G18: 11.4 | H18: 61 | I18: 1007.6 | J18: 3 | K18: 0
A19: 2015 | B19: 6 | C19: 0 | D19: 1.68 | E19: 1.61 | F19: 0.56 | G19: 8.3 | H19: 67.9 | I19: 1007 | J19: 8 | K19: 1
A20: 2015 | B20: 7 | C20: 0 | D20: 1.46 | E20: 1.41 | F20: 0.03 | G20: 7.5 | H20: 71.9 | I20: 1005.6 | J20: 8 | K20: 0 | M20: 42186 | N20: =SUM(C20:C22) -> 2
A21: 2015 | B21: 8 | C21: 1 | D21: 1.52 | E21: 1.6 | F21: -0.35 | G21: 7 | H21: 71.7 | I21: 1004.6 | J21: 1 | K21: 0
A22: 2015 | B22: 9 | C22: 1 | D22: 1.57 | E22: 1.58 | F22: 0.2 | G22: 8.3 | H22: 67.3 | I22: 1006.2 | J22: 7 | K22: 1
A23: 2015 | B23: 10 | C23: 1 | D23: 1.39 | E23: 1.38 | F23: -0.35 | G23: 9.8 | H23: 62.8 | I23: 1005.1 | J23: 0 | K23: 1 | M23: 42278 | N23: =SUM(C23:C25) -> 5
A24: 2015 | B24: 11 | C24: 3 | D24: 1.49 | E24: 1.4 | F24: 0.68 | G24: 9.5 | H24: 63.3 | I24: 1007.2 | J24: 5 | K24: 1
A25: 2015 | B25: 12 | C25: 1 | D25: 1.37 | E25: 1.34 | F25: 0.51 | G25: 11.5 | H25: 54 | I25: 1009 | J25: 0 | K25: 3
A26: 2016 | B26: 1 | C26: 0 | D26: -0.45 | E26: -0.49 | F26: 0.14 | G26: 12.3 | H26: 58 | I26: 1011.1 | J26: 1 | K26: 1 | M26: 42370 | N26: =SUM(C26:C28) -> 0
A27: 2016 | B27: 2 | C27: 0 | D27: -0.5 | E27: -0.51 | F27: 0.68 | G27: 12.9 | H27: 61.6 | I27: 1010.6 | J27: 0 | K27: 0
A28: 2016 | B28: 3 | C28: 0 | D28: -0.53 | E28: -0.46 | F28: -0.41 | G28: 13 | H28: 51 | I28: 1008.4 | J28: 0 | K28: 0
A29: 2016 | B29: 4 | C29: 0 | D29: -0.52 | E29: -0.6 | F29: 0.58 | G29: 11.4 | H29: 65 | I29: 1008.5 | J29: 5 | K29: 0 | M29: 42461 | N29: =SUM(C29:C31) -> 3
A30: 2016 | B30: 5 | C30: 0 | D30: -0.58 | E30: -0.58 | F30: 0.69 | G30: 10.7 | H30: 56 | I30: 1007.8 | J30: 1 | K30: 0
A31: 2016 | B31: 6 | C31: 3 | D31: -0.52 | E31: -0.52 | F31: 0.16 | G31: 7.4 | H31: 64.7 | I31: 1004.6 | J31: 8 | K31: 0
A32: 2016 | B32: 7 | C32: 1 | D32: -0.47 | E32: -0.49 | F32: -0.44 | G32: 8.2 | H32: 72.1 | I32: 1004.9 | J32: 3 | K32: 3 | M32: 42552 | N32: =SUM(C32:C34) -> 5
A33: 2016 | B33: 8 | C33: 2 | D33: -0.45 | E33: -0.47 | F33: 0.15 | G33: 8.4 | H33: 70.4 | I33: 1004.4 | J33: 7 | K33: 1
A34: 2016 | B34: 9 | C34: 2 | D34: -0.27 | E34: -0.2 | F34: -0.23 | G34: 8.9 | H34: 72.5 | I34: 1004.5 | J34: 7 | K34: 2
A35: 2016 | B35: 10 | C35: 5 | D35: -0.67 | E35: -0.63 | F35: -0.26 | G35: 9 | H35: 64.6 | I35: 1004.5 | J35: 0 | K35: 2 | M35: 42644 | N35: =SUM(C35:C37) -> 9
A36: 2016 | B36: 11 | C36: 3 | D36: -0.21 | E36: -0.12 | F36: 0.2 | G36: 9.8 | H36: 68 | I36: 1007.8 | J36: 4 | K36: 5
A37: 2016 | B37: 12 | C37: 1 | D37: -0.42 | E37: -0.31 | F37: -0.14 | G37: 11.8 | H37: 54.8 | I37: 1010.8 | J37: 7 | K37: 3
A38: 2017 | B38: 1 | C38: 0 | D38: 0.08 | E38: 0.06 | F38: 0.49 | G38: 12.2 | H38: 53.6 | I38: 1009.7 | J38: 7 | K38: 1 | M38: 42736 | N38: =SUM(C38:C40) -> 1
A39: 2017 | B39: 2 | C39: 0 | D39: -0.07 | E39: -0.02 | F39: -0.27 | G39: 12 | H39: 51.8 | I39: 1010.5 | J39: 4 | K39: 0
A40: 2017 | B40: 3 | C40: 1 | D40: -0.04 | E40: -0.03 | F40: 0.68 | G40: 11.5 | H40: 55.9 | I40: 1009.7 | J40: 3 | K40: 0
...
